Workbook

Sheet description
A1: Name | B1: Desc
A2: {=TRANSPOSE(tmdb_5000_movies!A1:Y1)} -> budget | B2: Biaya pembuatan
A3: genres | B3: Genre film (data mentah)
A4: genre_1 | B4: Genre film 1
A5: genre_2 | B5: Genre film 2
A6: genre_3 | B6: Genre film 3
A7: genre_4 | B7: Genre film 4
A8: homepage | B8: link halaman film
A9: id | B9: id film
A10: Title
A11: keywords | B11: keyword untuk film tersebut
A12: original_language | B12: bahasa yang digunakan
A13: overview | B13: gambaran singkat soal film tersebut
A14: popularity | B14: seberapa populer film ini
A15: production_companies | B15: perusahaan pembuat film ini
A16: Companies
A17: production_countries | B17: lokasi pembuatan film ini
A18: release_date | B18: tanggal rilis
A19: Year
A20: revenue | B20: estimasi yang didapatkan
A21: runtime | B21: durasi film (dalam menit)
A22: spoken_languages | B22: bahasa yang digunakan (serapan)
A23: status | B23: status film
A24: tagline | B24: tagline dari film tersebut
A25: vote_average | B25: rata-rata nilai vote
A26: vote_count | B26: jumlah yang vote
A27: profit

Sheet tes_dashboard

Sheet pivot
A1: genre_1 | B1: (All) | G1: genre_1 | H1: (All) | L1: Companies | M1: Universal Pictures
P2: popularity
A3: Companies | B3: Total Profit | C3: Total Budget | G3: Companies | H3: Total Popularity | L3: Row Labels | M3: Total Profit | N3: Total Popularity | R3: Berdasarkan total profit, paramount pictures menduduki posisi pertama yang diikuti oleh universal pictures dengan selisih pendapatan profit sebesar $ 452.121.987 namun
A4: Paramount Pictures | B4: 25082067469 | C4: 11989862948 | G4: Universal Pictures | H4: 7104638114 | L4: Minions | M4: 1082730962 | N4: 0.48517361 | P4: =GETPIVOTDATA("popularity",$G$3,"Companies","Universal Pictures")-GETPIVOTDATA("popularity",$G$3,"Companies","Paramount Pictures") -> 13176408 | R4: universal pictures menggunakan budget yang lebih sedikit dibandingkan paramount pictures yaitu selisih $ 1.866.434.296. Dari sini universal pictures mendapatkan
A5: Universal Pictures | B5: 24629945482 | C5: 10123428652 | G5: Paramount Pictures | H5: 7091461706 | L5: Despicable Me 2 | M5: 894761885 | N5: 0.075851113 | R5: keuntungan sebesar 24% dibandingkan dengan paramount pictures meskipun berada diurutan kedua berdasarkan profit yang diperoleh
A6: Walt Disney Pictures | B6: 19204470467 | C6: 9201780000 | G6: Columbia Pictures | H6: 5414298750 | L6: Lucy | M6: 86546825 | N6: 0.063857435
A7: Columbia Pictures | B7: 17670376626 | C7: 10192774736 | G7: Twentieth Century Fox Film Corporation | H7: 4780385911 | L7: Despicable Me | M7: 474513985 | N7: 0.063090691 | V7: =GETPIVOTDATA("Total Profit",$A$3,"Companies","Paramount Pictures")-GETPIVOTDATA("Total Profit",$A$3,"Companies","Universal Pictures") -> 452121987
A8: Twentieth Century Fox Film Corporation | B8: 16242464696 | C8: 6876440000 | G8: Walt Disney Pictures | H8: 4167392867 | L8: Bruce Almighty | M8: 404572835 | N8: 0.060778096 | R8: Berdasarkan analisis sebelumnya saya melanjutkan untuk mencari tahu apakah terdapat hubungan dengan popularitas yang diperoleh suatu company. Berdasarkan gambar diatas | V8: 452121987
A9: New Line Cinema | B9: 8552172273 | C9: 4641485000 | G9: New Line Cinema | H9: 3226314325 | L9: Schindler's List | M9: 299365567 | N9: 0.057888139 | R9: dapat dilihat bahwa universal pictures memiliki popularity 13.176.408 lebih banyak dari paramount pictures, hal ini berarti total popularitas yang diperoleh film suatu company tidak
A10: Village Roadshow Pictures | B10: 6951254238 | C10: 4867800003 | G10: Village Roadshow Pictures | H10: 2257235739 | L10: Furious 7 | M10: 1316249360 | N10: 0.056698378 | R10: bergantung dengan total profit yang diperoleh | V10: =GETPIVOTDATA("Total Budget",$A$3,"Companies","Paramount Pictures")-GETPIVOTDATA("Total Budget",$A$3,"Companies","Universal Pictures") -> 1866434296
A11: DreamWorks SKG | B11: 6298102144 | C11: 3081500000 | G11: Summit Entertainment | H11: 1610148976 | L11: The Bourne Identity | M11: 154034224 | N11: 0.047918188
A12: Lucasfilm | B12: 5810309700 | C12: 796427000 | G12: Miramax Films | H12: 1513740164 | L12: The Purge: Anarchy | M12: 99782847 | N12: 0.045978241 | R12: Popularitas film tertinggi yang diproduksi oleh universal pictures adala "Minions" meskipun profit yang diperolah lebih besar "Furious 7". Film "Minions" menyumbang | T12: =GETPIVOTDATA("Total Popularity",$L$3)/GETPIVOTDATA("popularity",$G$3,"Companies","Universal Pictures") -> 1.4075312e-10
A13: Marvel Studios | B13: 5551826201 | C13: 1750000000 | G13: DreamWorks SKG | H13: 1427649268 | L13: Snow White and the Huntsman | M13: 226600000 | N13: 0.042766104 | R13: sebesar 12,32% dari seluruh total popularitas yang diperoleh universal pictures. Sedangkan untuk urutan top 10, "Minions" memberikan kontribusi sebesar 48,52%, hal ini menunjukkan | V13: =V7/V10 -> 0.24223836
A14: Grand Total | B14: 135992989296 | C14: 63521498339 | G14: Grand Total | H14: 38593265820 | L14: Grand Total | M14: 5039158490 | N14: 1 | R14: bahwa "Minions" memberikan kontribusi yang sangat besar terhadap popularitas yang diperoleh universal pictures
A16: Companies | B16: Paramount Pictures
D17: Companies | E17: Paramount Pictures
A18: Row Labels | B18: Sum of Profit
A19: Action | B19: 5358895700 | D19: Sum of Profit | E19: Column Labels
A20: Drama | B20: 4706520363 | D20: Row Labels | E20: Action | F20: Grand Total
A21: Science Fiction | B21: 4102301748 | D21: Transformers: Dark of the Moon | E21: 928746996 | F21: 928746996
A22: Adventure | B22: 3584612644 | D22: Mission: Impossible - Ghost Protocol | E22: 549713380 | F22: 549713380
A23: Comedy | B23: 3164373506 | D23: Mission: Impossible - Rogue Nation | E23: 532330139 | F23: 532330139
A24: Fantasy | B24: 948469419 | D24: Top Gun | E24: 341830601 | F24: 341830601
A25: Crime | B25: 850466534 | D25: World War Z | E25: 331865000 | F25: 331865000
A26: Horror | B26: 843244359 | D26: Beverly Hills Cop | E26: 301360478 | F26: 301360478
A27: Thriller | B27: 690221099 | D27: Beverly Hills Cop II | E27: 279965036 | F27: 279965036
A28: Animation | B28: 480259427 | D28: Star Trek Into Darkness | E28: 277365246 | F28: 277365246
A29: Romance | B29: 162428050 | D29: The Hunt for Red October | E29: 169200000 | F29: 169200000
A30: Music | B30: 128113269 | D30: The Last Airbender | E30: 168502923 | F30: 168502923
A31: Documentary | B31: 80009268 | D31: Face/Off | E31: 165676146 | F31: 165676146
A32: War | B32: 30770585 | D32: Star Trek Beyond | E32: 158471816 | F32: 158471816
... A37: Grand Total | B37: 25082067469 | D37: Beverly Hills Cop III | E37: 69208989 | F37: 69208989
D38: Deep Impact | E38: 65464664 | F38: 65464664
D39: Jackass Number Two | E39: 61778712 | F39: 61778712
D40: Lara Croft Tomb Raider: The Cradle of Life | E40: 61505388 | F40: 61505388
D41: Shaft | E41: 61196498 | F41: 61196498
D42: Watchmen | E42: 55258983 | F42: 55258983
D43: The Golden Child | E43: 54817939 | F43: 54817939
D44: Without a Paddle | E44: 50631118 | F44: 50631118
D45: Changing Lanes | E45: 49935764 | F45: 49935764
...

Sheet tmdb_5000_movies
A1: budget | B1: genres | C1: genre_1 | D1: genre_2 | E1: genre_3 | F1: genre_4 | G1: homepage | H1: id | I1: Title | J1: keywords | K1: original_language | L1: overview | M1: popularity | N1: production_companies | O1: Companies | P1: production_countries | Q1: release_date | R1: Year | S1: revenue | T1: runtime | U1: spoken_languages | V1: status | W1: tagline | X1: vote_average | Y1: vote_count | Z1: Profit
A2: 237000000 | B2: [{ 28, name: Action}, { 12, name: Adventure}, { 14, name: Fantasy}, { 878, name: Science Fiction}] | C2: Action | D2: Adventure | E2: Fantasy | F2: Science Fiction | G2: http://www.avatarmovie.com/ | H2: 19995 | I2: Avatar | J2: [{"id": 1463, "name": "culture clash"}, {"id": 2964, "name": "future"}, {"id": 3386, "name": "space war"}, {"id": 3388, "name": "space colony"}, {"id": 3679, "name": "society"}, {"id": 3801, "name": "space travel"}, {"id": 9685, "name": "futuristic"}, {"id": 9840, "name": "romance"}, {"id": 9882, "name": "space"}, {"id": 9951, "name": "alien"}, {"id": 10148, "name": "tribe"}, {"id": 10158, "name": "alien planet"}, {"id": 10987, "name": "cgi"}, {"id": 11399, "name": "marine"}, {"id": 13065, "name": "soldier"}, {"id": 14643, "name": "battle"}, {"id": 14720, "name": "love affair"}, {"id": 165431, "name": "anti war"}, {"id": 193554, "name": "power relations"}, {"id": 206690, "name": "mind and soul"}, {"id": 209714, "name": "3d"}] | K2: en | L2: In the 22nd century, a paraplegic Marine is dispatched to the moon Pandora on a unique mission, but becomes torn between following orders and protecting an alien civilization. | M2: 150437577 | N2: [{"name": "Ingenious Film Partners", "id": 289}, {"name": "Twentieth Century Fox Film Corporation", "id": 306}, {"name": "Dune Entertainment", "id": 444}, {"name": "Lightstorm Entertainment", "id": 574}] | O2: Ingenious Film Partners | P2: [{"iso_3166_1": "US", "name": "United States of America"}, {"iso_3166_1": "GB", "name": "United Kingdom"}] | Q2: 40157 | R2: 2009 | S2: 2787965087 | T2: 162 | U2: [{"iso_639_1": "en", "name": "English"}, {"iso_639_1": "es", "name": "Espa\u00f1ol"}] | V2: Released | W2: Enter the World of Pandora. | X2: 7.2 | Y2: 11800 | Z2: 2550965087
A3: 300000000 | B3: [{ 12, name: Adventure}, { 14, name: Fantasy}, { 28, name: Action}] | C3: Adventure | D3: Fantasy | E3: Action | F3: - | G3: http://disney.go.com/disneypictures/pirates/ | H3: 285 | I3: Pirates of the Caribbean: At World's End | J3: [{"id": 270, "name": "ocean"}, {"id": 726, "name": "drug abuse"}, {"id": 911, "name": "exotic island"}, {"id": 1319, "name": "east india trading company"}, {"id": 2038, "name": "love of one's life"}, {"id": 2052, "name": "traitor"}, {"id": 2580, "name": "shipwreck"}, {"id": 2660, "name": "strong woman"}, {"id": 3799, "name": "ship"}, {"id": 5740, "name": "alliance"}, {"id": 5941, "name": "calypso"}, {"id": 6155, "name": "afterlife"}, {"id": 6211, "name": "fighter"}, {"id": 12988, "name": "pirate"}, {"id": 157186, "name": "swashbuckler"}, {"id": 179430, "name": "aftercreditsstinger"}] | K3: en | L3: Captain Barbossa, long believed to be dead, has come back to life and is headed to the edge of the Earth with Will Turner and Elizabeth Swann. But nothing is quite as it seems. | M3: 139082615 | N3: [{"name": "Walt Disney Pictures", "id": 2}, {"name": "Jerry Bruckheimer Films", "id": 130}, {"name": "Second Mate Productions", "id": 19936}] | O3: Walt Disney Pictures | P3: [{"iso_3166_1": "US", "name": "United States of America"}] | Q3: 39221 | R3: 2007 | S3: 961000000 | T3: 169 | U3: [{"iso_639_1": "en", "name": "English"}] | V3: Released | W3: At the end of the world, the adventure begins. | X3: 6.9 | Y3: 4500 | Z3: 661000000
A4: 245000000 | B4: [{ 28, name: Action}, { 12, name: Adventure}, { 80, name: Crime}] | C4: Action | D4: Adventure | E4: Crime | F4: - | G4: http://www.sonypictures.com/movies/spectre/ | H4: 206647 | I4: Spectre | J4: [{"id": 470, "name": "spy"}, {"id": 818, "name": "based on novel"}, {"id": 4289, "name": "secret agent"}, {"id": 9663, "name": "sequel"}, {"id": 14555, "name": "mi6"}, {"id": 156095, "name": "british secret service"}, {"id": 158431, "name": "united kingdom"}] | K4: en | L4: A cryptic message from Bondâ€™s past sends him on a trail to uncover a sinister organization. While M battles political forces to keep the secret service alive, Bond peels back the layers of deceit to reveal the terrible truth behind SPECTRE. | M4: 107376788 | N4: [{"name": "Columbia Pictures", "id": 5}, {"name": "Danjaq", "id": 10761}, {"name": "B24", "id": 69434}] | O4: Columbia Pictures | P4: [{"iso_3166_1": "GB", "name": "United Kingdom"}, {"iso_3166_1": "US", "name": "United States of America"}] | Q4: 42303 | R4: 2015 | S4: 880674609 | T4: 148 | U4: [{"iso_639_1": "fr", "name": "Fran\u00e7ais"}, {"iso_639_1": "en", "name": "English"}, {"iso_639_1": "es", "name": "Espa\u00f1ol"}, {"iso_639_1": "it", "name": "Italiano"}, {"iso_639_1": "de", "name": "Deutsch"}] | V4: Released | W4: A Plan No One Escapes | X4: 6.3 | Y4: 4466 | Z4: 635674609
A5: 250000000 | B5: [{ 28, name: Action}, { 80, name: Crime}, { 18, name: Drama}, { 53, name: Thriller}] | C5: Action | D5: Crime | E5: Drama | F5: Thriller | G5: http://www.thedarkknightrises.com/ | H5: 49026 | I5: The Dark Knight Rises | J5: [{"id": 849, "name": "dc comics"}, {"id": 853, "name": "crime fighter"}, {"id": 949, "name": "terrorist"}, {"id": 1308, "name": "secret identity"}, {"id": 1437, "name": "burglar"}, {"id": 3051, "name": "hostage drama"}, {"id": 3562, "name": "time bomb"}, {"id": 6969, "name": "gotham city"}, {"id": 7002, "name": "vigilante"}, {"id": 9665, "name": "cover-up"}, {"id": 9715, "name": "superhero"}, {"id": 9990, "name": "villainess"}, {"id": 10044, "name": "tragic hero"}, {"id": 13015, "name": "terrorism"}, {"id": 14796, "name": "destruction"}, {"id": 18933, "name": "catwoman"}, {"id": 156082, "name": "cat burglar"}, {"id": 156395, "name": "imax"}, {"id": 173272, "name": "flood"}, {"id": 179093, "name": "criminal underworld"}, {"id": 230775, "name": "batman"}] | K5: en | L5: Following the death of District Attorney Harvey Dent, Batman assumes responsibility for Dent's crimes to protect the late attorney's reputation and is subsequently hunted by the Gotham City Police Department. Eight years later, Batman encounters the mysterious Selina Kyle and the villainous Bane, a new terrorist leader who overwhelms Gotham's finest. The Dark Knight resurfaces to protect a city that has branded him an enemy. | M5: 11231295 | N5: [{"name": "Legendary Pictures", "id": 923}, {"name": "Warner Bros.", "id": 6194}, {"name": "DC Entertainment", "id": 9993}, {"name": "Syncopy", "id": 9996}] | O5: Legendary Pictures | P5: [{"iso_3166_1": "US", "name": "United States of America"}] | Q5: 41106 | R5: 2012 | S5: 1084939099 | T5: 165 | U5: [{"iso_639_1": "en", "name": "English"}] | V5: Released | W5: The Legend Ends | X5: 7.6 | Y5: 9106 | Z5: 834939099
A6: 260000000 | B6: [{ 28, name: Action}, { 12, name: Adventure}, { 878, name: Science Fiction}] | C6: Action | D6: Adventure | E6: Science Fiction | F6: - | G6: http://movies.disney.com/john-carter | H6: 49529 | I6: John Carter | J6: [{"id": 818, "name": "based on novel"}, {"id": 839, "name": "mars"}, {"id": 1456, "name": "medallion"}, {"id": 3801, "name": "space travel"}, {"id": 7376, "name": "princess"}, {"id": 9951, "name": "alien"}, {"id": 10028, "name": "steampunk"}, {"id": 10539, "name": "martian"}, {"id": 10685, "name": "escape"}, {"id": 161511, "name": "edgar rice burroughs"}, {"id": 163252, "name": "alien race"}, {"id": 179102, "name": "superhuman strength"}, {"id": 190320, "name": "mars civilization"}, {"id": 195446, "name": "sword and planet"}, {"id": 207928, "name": "19th century"}, {"id": 209714, "name": "3d"}] | K6: en | L6: John Carter is a war-weary, former military captain who's inexplicably transported to the mysterious and exotic planet of Barsoom (Mars) and reluctantly becomes embroiled in an epic conflict. It's a world on the brink of collapse, and Carter rediscovers his humanity when he realizes the survival of Barsoom and its people rests in his hands. | M6: 43926995 | N6: [{"name": "Walt Disney Pictures", "id": 2}] | O6: Walt Disney Pictures | P6: [{"iso_3166_1": "US", "name": "United States of America"}] | Q6: 40975 | R6: 2012 | S6: 284139100 | T6: 132 | U6: [{"iso_639_1": "en", "name": "English"}] | V6: Released | W6: Lost in our world, found in another. | X6: 6.1 | Y6: 2124 | Z6: 24139100
A7: 258000000 | B7: [{ 14, name: Fantasy}, { 28, name: Action}, { 12, name: Adventure}] | C7: Fantasy | D7: Action | E7: Adventure | F7: - | G7: http://www.sonypictures.com/movies/spider-man3/ | H7: 559 | I7: Spider-Man 3 | J7: [{"id": 851, "name": "dual identity"}, {"id": 1453, "name": "amnesia"}, {"id": 1965, "name": "sandstorm"}, {"id": 2038, "name": "love of one's life"}, {"id": 3446, "name": "forgiveness"}, {"id": 3986, "name": "spider"}, {"id": 4391, "name": "wretch"}, {"id": 4959, "name": "death of a friend"}, {"id": 5776, "name": "egomania"}, {"id": 5789, "name": "sand"}, {"id": 5857, "name": "narcism"}, {"id": 6062, "name": "hostility"}, {"id": 8828, "name": "marvel comic"}, {"id": 9663, "name": "sequel"}, {"id": 9715, "name": "superhero"}, {"id": 9748, "name": "revenge"}] | K7: en | L7: The seemingly invincible Spider-Man goes up against an all-new crop of villain â€“ including the shape-shifting Sandman. While Spider-Manâ€™s superpowers are altered by an alien organism, his alter ego, Peter Parker, deals with nemesis Eddie Brock and also gets caught up in a love triangle. | M7: 115699814 | N7: [{"name": "Columbia Pictures", "id": 5}, {"name": "Laura Ziskin Productions", "id": 326}, {"name": "Marvel Enterprises", "id": 19551}] | O7: Columbia Pictures | P7: [{"iso_3166_1": "US", "name": "United States of America"}] | Q7: 39203 | R7: 2007 | S7: 890871626 | T7: 139 | U7: [{"iso_639_1": "en", "name": "English"}, {"iso_639_1": "fr", "name": "Fran\u00e7ais"}] | V7: Released | W7: The battle within. | X7: 5.9 | Y7: 3576 | Z7: 632871626
A8: 260000000 | B8: [{ 16, name: Animation}, { 10751, name: Family}] | C8: Animation | D8: Family | E8: - | F8: - | G8: http://disney.go.com/disneypictures/tangled/ | H8: 38757 | I8: Tangled | J8: [{"id": 1562, "name": "hostage"}, {"id": 2343, "name": "magic"}, {"id": 2673, "name": "horse"}, {"id": 3205, "name": "fairy tale"}, {"id": 4344, "name": "musical"}, {"id": 7376, "name": "princess"}, {"id": 10336, "name": "animation"}, {"id": 33787, "name": "tower"}, {"id": 155658, "name": "blonde woman"}, {"id": 162219, "name": "selfishness"}, {"id": 163545, "name": "healing power"}, {"id": 179411, "name": "based on fairy tale"}, {"id": 179431, "name": "duringcreditsstinger"}, {"id": 215258, "name": "healing gift"}, {"id": 234183, "name": "animal sidekick"}] | K8: en | L8: When the kingdom's most wanted-and most charming-bandit Flynn Rider hides out in a mysterious tower, he's taken hostage by Rapunzel, a beautiful and feisty tower-bound teen with 70 feet of magical, golden hair. Flynn's curious captor, who's looking for her ticket out of the tower where she's been locked away for years, strikes a deal with the handsome thief and the unlikely duo sets off on an action-packed escapade, complete with a super-cop horse, an over-protective chameleon and a gruff gang of pub thugs. | M8: 48681969 | N8: [{"name": "Walt Disney Pictures", "id": 2}, {"name": "Walt Disney Animation Studios", "id": 6125}] | O8: Walt Disney Pictures | P8: [{"iso_3166_1": "US", "name": "United States of America"}] | Q8: 40506 | R8: 2010 | S8: 591794936 | T8: 100 | U8: [{"iso_639_1": "en", "name": "English"}] | V8: Released | W8: They're taking adventure to new lengths. | X8: 7.4 | Y8: 3330 | Z8: 331794936
A9: 280000000 | B9: [{ 28, name: Action}, { 12, name: Adventure}, { 878, name: Science Fiction}] | C9: Action | D9: Adventure | E9: Science Fiction | F9: - | G9: http://marvel.com/movies/movie/193/avengers_age_of_ultron | H9: 99861 | I9: Avengers: Age of Ultron | J9: [{"id": 8828, "name": "marvel comic"}, {"id": 9663, "name": "sequel"}, {"id": 9715, "name": "superhero"}, {"id": 9717, "name": "based on comic book"}, {"id": 10629, "name": "vision"}, {"id": 155030, "name": "superhero team"}, {"id": 179431, "name": "duringcreditsstinger"}, {"id": 180547, "name": "marvel cinematic universe"}, {"id": 209714, "name": "3d"}] | K9: en | L9: When Tony Stark tries to jumpstart a dormant peacekeeping program, things go awry and Earthâ€™s Mightiest Heroes are put to the ultimate test as the fate of the planet hangs in the balance. As the villainous Ultron emerges, it is up to The Avengers to stop him from enacting his terrible plans, and soon uneasy alliances and unexpected action pave the way for an epic and unique global adventure. | M9: 134279229 | N9: [{"name": "Marvel Studios", "id": 420}, {"name": "Prime Focus", "id": 15357}, {"name": "Revolution Sun Studios", "id": 76043}] | O9: Marvel Studios | P9: [{"iso_3166_1": "US", "name": "United States of America"}] | Q9: 42116 | R9: 2015 | S9: 1405403694 | T9: 141 | U9: [{"iso_639_1": "en", "name": "English"}] | V9: Released | W9: A New Age Has Come. | X9: 7.3 | Y9: 6767 | Z9: 1125403694
A10: 250000000 | B10: [{ 12, name: Adventure}, { 14, name: Fantasy}, { 10751, name: Family}] | C10: Adventure | D10: Fantasy | E10: Family | F10: - | G10: http://harrypotter.warnerbros.com/harrypotterandthehalf-bloodprince/dvd/index.html | H10: 767 | I10: Harry Potter and the Half-Blood Prince | J10: [{"id": 616, "name": "witch"}, {"id": 2343, "name": "magic"}, {"id": 3872, "name": "broom"}, {"id": 3884, "name": "school of witchcraft"}, {"id": 6333, "name": "wizardry"}, {"id": 10164, "name": "apparition"}, {"id": 10791, "name": "teenage crush"}, {"id": 12564, "name": "werewolf"}] | K10: en | L10: As Harry begins his sixth year at Hogwarts, he discovers an old book marked as 'Property of the Half-Blood Prince', and begins to learn more about Lord Voldemort's dark past. | M10: 98885637 | N10: [{"name": "Warner Bros.", "id": 6194}, {"name": "Heyday Films", "id": 7364}] | O10: Warner Bros. | P10: [{"iso_3166_1": "GB", "name": "United Kingdom"}, {"iso_3166_1": "US", "name": "United States of America"}] | Q10: 40001 | R10: 2009 | S10: 933959197 | T10: 153 | U10: [{"iso_639_1": "en", "name": "English"}] | V10: Released | W10: Dark Secrets Revealed | X10: 7.4 | Y10: 5293 | Z10: 683959197
A11: 250000000 | B11: [{ 28, name: Action}, { 12, name: Adventure}, { 14, name: Fantasy}] | C11: Action | D11: Adventure | E11: Fantasy | F11: - | G11: http://www.batmanvsupermandawnofjustice.com/ | H11: 209112 | I11: Batman v Superman: Dawn of Justice | J11: [{"id": 849, "name": "dc comics"}, {"id": 7002, "name": "vigilante"}, {"id": 9715, "name": "superhero"}, {"id": 9717, "name": "based on comic book"}, {"id": 9748, "name": "revenge"}, {"id": 163455, "name": "super powers"}, {"id": 195242, "name": "clark kent"}, {"id": 195243, "name": "bruce wayne"}, {"id": 229266, "name": "dc extended universe"}] | K11: en | L11: Fearing the actions of a god-like Super Hero left unchecked, Gotham Cityâ€™s own formidable, forceful vigilante takes on Metropolisâ€™s most revered, modern-day savior, while the world wrestles with what sort of hero it really needs. And with Batman and Superman at war with one another, a new threat quickly arises, putting mankind in greater danger than itâ€™s ever known before. | M11: 155790452 | N11: [{"name": "DC Comics", "id": 429}, {"name": "Atlas Entertainment", "id": 507}, {"name": "Warner Bros.", "id": 6194}, {"name": "DC Entertainment", "id": 9993}, {"name": "Cruel & Unusual Films", "id": 9995}, {"name": "RatPac-Dune Entertainment", "id": 41624}] | O11: DC Comics | P11: [{"iso_3166_1": "US", "name": "United States of America"}] | Q11: 42452 | R11: 2016 | S11: 873260194 | T11: 151 | U11: [{"iso_639_1": "en", "name": "English"}] | V11: Released | W11: Justice or revenge | X11: 5.7 | Y11: 7004 | Z11: 623260194
A12: 270000000 | B12: [{ 12, name: Adventure}, { 14, name: Fantasy}, { 28, name: Action}, { 878, name: Science Fiction}] | C12: Adventure | D12: Fantasy | E12: Action | F12: Science Fiction | G12: http://www.superman.com | H12: 1452 | I12: Superman Returns | J12: [{"id": 83, "name": "saving the world"}, {"id": 849, "name": "dc comics"}, {"id": 8872, "name": "invulnerability"}, {"id": 9663, "name": "sequel"}, {"id": 9715, "name": "superhero"}, {"id": 9717, "name": "based on comic book"}, {"id": 163420, "name": "kryptonite"}, {"id": 163455, "name": "super powers"}, {"id": 179102, "name": "superhuman strength"}, {"id": 202526, "name": "lex luthor"}] | K12: en | L12: Superman returns to discover his 5-year absence has allowed Lex Luthor to walk free, and that those he was closest too felt abandoned and have moved on. Luthor plots his ultimate revenge that could see millions killed and change the face of the planet forever, as well as ridding himself of the Man of Steel. | M12: 57925623 | N12: [{"name": "DC Comics", "id": 429}, {"name": "Legendary Pictures", "id": 923}, {"name": "Warner Bros.", "id": 6194}, {"name": "Bad Hat Harry Productions", "id": 9168}] | O12: DC Comics | P12: [{"iso_3166_1": "US", "name": "United States of America"}] | Q12: 38896 | R12: 2006 | S12: 391081192 | T12: 154 | U12: [{"iso_639_1": "en", "name": "English"}, {"iso_639_1": "fr", "name": "Fran\u00e7ais"}, {"iso_639_1": "de", "name": "Deutsch"}] | V12: Released | X12: 5.4 | Y12: 1400 | Z12: 121081192
A13: 200000000 | B13: [{ 12, name: Adventure}, { 28, name: Action}, { 53, name: Thriller}, { 80, name: Crime}] | C13: Adventure | D13: Action | E13: Thriller | F13: Crime | G13: http://www.mgm.com/view/movie/234/Quantum-of-Solace/ | H13: 10764 | I13: Quantum of Solace | J13: [{"id": 627, "name": "killing"}, {"id": 1568, "name": "undercover"}, {"id": 4289, "name": "secret agent"}, {"id": 156095, "name": "british secret service"}] | K13: en | L13: Quantum of Solace continues the adventures of James Bond after Casino Royale. Betrayed by Vesper, the woman he loved, 007 fights the urge to make his latest mission personal. Pursuing his determination to uncover the truth, Bond and M interrogate Mr. White, who reveals that the organization that blackmailed Vesper is far more complex and dangerous than anyone had imagined. | M13: 107928811 | N13: [{"name": "Eon Productions", "id": 7576}] | O13: Eon Productions | P13: [{"iso_3166_1": "GB", "name": "United Kingdom"}, {"iso_3166_1": "US", "name": "United States of America"}] | Q13: 39751 | R13: 2008 | S13: 586090727 | T13: 106 | U13: [{"iso_639_1": "en", "name": "English"}, {"iso_639_1": "es", "name": "Espa\u00f1ol"}, {"iso_639_1": "it", "name": "Italiano"}, {"iso_639_1": "fr", "name": "Fran\u00e7ais"}, {"iso_639_1": "de", "name": "Deutsch"}] | V13: Released | W13: For love, for hate, for justice, for revenge. | X13: 6.1 | Y13: 2965 | Z13: 386090727
A14: 200000000 | B14: [{ 12, name: Adventure}, { 14, name: Fantasy}, { 28, name: Action}] | C14: Adventure | D14: Fantasy | E14: Action | F14: - | G14: http://disney.go.com/disneypictures/pirates/ | H14: 58 | I14: Pirates of the Caribbean: Dead Man's Chest | J14: [{"id": 616, "name": "witch"}, {"id": 663, "name": "fortune teller"}, {"id": 910, "name": "bondage"}, {"id": 911, "name": "exotic island"}, {"id": 1299, "name": "monster"}, {"id": 1316, "name": "captain"}, {"id": 1317, "name": "card game"}, {"id": 1319, "name": "east india trading company"}, {"id": 1461, "name": "compass"}, {"id": 3799, "name": "ship"}, {"id": 5600, "name": "daughter"}, {"id": 12988, "name": "pirate"}, {"id": 157186, "name": "swashbuckler"}, {"id": 179430, "name": "aftercreditsstinger"}] | K14: en | L14: Captain Jack Sparrow works his way out of a blood debt with the ghostly Davey Jones, he also attempts to avoid eternal damnation. | M14: 145847379 | N14: [{"name": "Walt Disney Pictures", "id": 2}, {"name": "Jerry Bruckheimer Films", "id": 130}, {"name": "Second Mate Productions", "id": 19936}] | O14: Walt Disney Pictures | P14: [{"iso_3166_1": "JM", "name": "Jamaica"}, {"iso_3166_1": "US", "name": "United States of America"}, {"iso_3166_1": "BS", "name": "Bahamas"}, {"iso_3166_1": "DM", "name": "Dominica"}] | Q14: 38888 | R14: 2006 | S14: 1065659812 | T14: 151 | U14: [{"iso_639_1": "en", "name": "English"}, {"iso_639_1": "tr", "name": "T\u00fcrk\u00e7e"}, {"iso_639_1": "el", "name": "\u03b5\u03bb\u03bb\u03b7\u03bd\u03b9\u03ba\u03ac"}, {"iso_639_1": "zh", "name": "\u666e\u901a\u8bdd"}] | V14: Released | W14: Jack is back! | X14: 7.0 | Y14: 5246 | Z14: 865659812
A15: 255000000 | B15: [{ 28, name: Action}, { 12, name: Adventure}, { 37, name: Western}] | C15: Action | D15: Adventure | E15: Western | F15: - | G15: http://disney.go.com/the-lone-ranger/ | H15: 57201 | I15: The Lone Ranger | J15: [{"id": 1556, "name": "texas"}, {"id": 2673, "name": "horse"}, {"id": 5385, "name": "survivor"}, {"id": 5901, "name": "texas ranger"}, {"id": 9104, "name": "partner"}, {"id": 9503, "name": "outlaw"}, {"id": 10685, "name": "escape"}, {"id": 10909, "name": "lawyer"}, {"id": 13008, "name": "train"}, {"id": 178867, "name": "lone ranger"}, {"id": 179419, "name": "comanche"}, {"id": 222787, "name": "the lone ranger"}, {"id": 228232, "name": "tonto"}] | K15: en | L15: The Texas Rangers chase down a gang of outlaws led by Butch Cavendish, but the gang ambushes the Rangers, seemingly killing them all. One survivor is found, however, by an American Indian named Tonto, who nurses him back to health. The Ranger, donning a mask and riding a white stallion named Silver, teams up with Tonto to bring the unscrupulous gang and others of that ilk to justice. | M15: 49046956 | N15: [{"name": "Walt Disney Pictures", "id": 2}, {"name": "Jerry Bruckheimer Films", "id": 130}, {"name": "Infinitum Nihil", "id": 2691}, {"name": "Silver Bullet Productions (II)", "id": 37380}, {"name": "Blind Wink Productions", "id": 37381}, {"name": "Classic Media", "id": 37382}] | O15: Walt Disney Pictures | P15: [{"iso_3166_1": "US", "name": "United States of America"}] | Q15: 41458 | R15: 2013 | S15: 89289910 | T15: 149 | U15: [{"iso_639_1": "en", "name": "English"}] | V15: Released | W15: Never Take Off the Mask | X15: 5.9 | Y15: 2311 | Z15: -165710090
A16: 225000000 | B16: [{ 28, name: Action}, { 12, name: Adventure}, { 14, name: Fantasy}, { 878, name: Science Fiction}] | C16: Action | D16: Adventure | E16: Fantasy | F16: Science Fiction | G16: http://www.manofsteel.com/ | H16: 49521 | I16: Man of Steel | J16: [{"id": 83, "name": "saving the world"}, {"id": 849, "name": "dc comics"}, {"id": 9715, "name": "superhero"}, {"id": 9717, "name": "based on comic book"}, {"id": 10761, "name": "superhuman"}, {"id": 14909, "name": "alien invasion"}, {"id": 161184, "name": "reboot"}, {"id": 163455, "name": "super powers"}, {"id": 229266, "name": "dc extended universe"}] | K16: en | L16: A young boy learns that he has extraordinary powers and is not of this earth. As a young man, he journeys to discover where he came from and what he was sent here to do. But the hero in him must emerge if he is to save the world from annihilation and become the symbol of hope for all mankind. | M16: 99398009 | N16: [{"name": "Legendary Pictures", "id": 923}, {"name": "Warner Bros.", "id": 6194}, {"name": "DC Entertainment", "id": 9993}, {"name": "Syncopy", "id": 9996}, {"name": "Cruel and Unusual Films", "id": 78685}] | O16: Legendary Pictures | P16: [{"iso_3166_1": "GB", "name": "United Kingdom"}, {"iso_3166_1": "US", "name": "United States of America"}] | Q16: 41437 | R16: 2013 | S16: 662845518 | T16: 143 | U16: [{"iso_639_1": "en", "name": "English"}] | V16: Released | W16: You will believe that a man can fly. | X16: 6.5 | Y16: 6359 | Z16: 437845518
A17: 225000000 | B17: [{ 12, name: Adventure}, { 10751, name: Family}, { 14, name: Fantasy}] | C17: Adventure | D17: Family | E17: Fantasy | F17: - | H17: 2454 | I17: The Chronicles of Narnia: Prince Caspian | J17: [{"id": 818, "name": "based on novel"}, {"id": 855, "name": "fictional place"}, {"id": 1155, "name": "brother sister relationship"}, {"id": 2043, "name": "lion"}, {"id": 3714, "name": "human being"}, {"id": 4391, "name": "wretch"}, {"id": 4820, "name": "leap in time"}, {"id": 5144, "name": "matter of life and death"}, {"id": 6150, "name": "faith"}, {"id": 6464, "name": "uncle"}, {"id": 166930, "name": "narnia"}, {"id": 170362, "name": "fantasy world"}] | K17: en | L17: One year after their incredible adventures in the Lion, the Witch and the Wardrobe, Peter, Edmund, Lucy and Susan Pevensie return to Narnia to aid a young prince whose life has been threatened by the evil King Miraz. Now, with the help of a colorful cast of new characters, including Trufflehunter the badger and Nikabrik the dwarf, the Pevensie clan embarks on an incredible quest to ensure that Narnia is returned to its rightful heir. | M17: 53978602 | N17: [{"name": "Walt Disney", "id": 5888}, {"name": "Walden Media", "id": 10221}, {"name": "Stillking Films", "id": 11345}, {"name": "Ozumi Films", "id": 11440}, {"name": "Propeler", "id": 11441}, {"name": "Silverbell Films", "id": 11442}, {"name": "Revolution Sun Studios", "id": 76043}] | O17: Walt Disney | P17: [{"iso_3166_1": "CZ", "name": "Czech Republic"}, {"iso_3166_1": "PL", "name": "Poland"}, {"iso_3166_1": "SI", "name": "Slovenia"}, {"iso_3166_1": "US", "name": "United States of America"}] | Q17: 39583 | R17: 2008 | S17: 419651413 | T17: 150 | U17: [{"iso_639_1": "en", "name": "English"}] | V17: Released | W17: Hope has a new face. | X17: 6.3 | Y17: 1630 | Z17: 194651413
A18: 220000000 | B18: [{ 878, name: Science Fiction}, { 28, name: Action}, { 12, name: Adventure}] | C18: Science Fiction | D18: Action | E18: Adventure | F18: - | G18: http://marvel.com/avengers_movie/ | H18: 24428 | I18: The Avengers | J18: [{"id": 242, "name": "new york"}, {"id": 5539, "name": "shield"}, {"id": 8828, "name": "marvel comic"}, {"id": 9715, "name": "superhero"}, {"id": 9717, "name": "based on comic book"}, {"id": 14909, "name": "alien invasion"}, {"id": 155030, "name": "superhero team"}, {"id": 179430, "name": "aftercreditsstinger"}, {"id": 179431, "name": "duringcreditsstinger"}, {"id": 180547, "name": "marvel cinematic universe"}] | K18: en | L18: When an unexpected enemy emerges and threatens global safety and security, Nick Fury, director of the international peacekeeping agency known as S.H.I.E.L.D., finds himself in need of a team to pull the world back from the brink of disaster. Spanning the globe, a daring recruitment effort begins! | M18: 144448633 | N18: [{"name": "Paramount Pictures", "id": 4}, {"name": "Marvel Studios", "id": 420}] | O18: Paramount Pictures | P18: [{"iso_3166_1": "US", "name": "United States of America"}] | Q18: 41024 | R18: 2012 | S18: 1519557910 | T18: 143 | U18: [{"iso_639_1": "en", "name": "English"}] | V18: Released | W18: Some assembly required. | X18: 7.4 | Y18: 11776 | Z18: 1299557910
A19: 380000000 | B19: [{ 12, name: Adventure}, { 28, name: Action}, { 14, name: Fantasy}] | C19: Adventure | D19: Action | E19: Fantasy | F19: - | G19: http://disney.go.com/pirates/index-on-stranger-tides.html#/video/ | H19: 1865 | I19: Pirates of the Caribbean: On Stranger Tides | J19: [{"id": 658, "name": "sea"}, {"id": 1316, "name": "captain"}, {"id": 1860, "name": "mutiny"}, {"id": 1938, "name": "sword"}, {"id": 2569, "name": "prime minister"}, {"id": 3180, "name": "sailing"}, {"id": 3625, "name": "silver"}, {"id": 3799, "name": "ship"}, {"id": 4235, "name": "duke"}, {"id": 5938, "name": "mermaid"}, {"id": 12988, "name": "pirate"}, {"id": 13065, "name": "soldier"}, {"id": 14643, "name": "battle"}, {"id": 157186, "name": "swashbuckler"}, {"id": 179430, "name": "aftercreditsstinger"}, {"id": 209714, "name": "3d"}] | K19: en | L19: Captain Jack Sparrow crosses paths with a woman from his past, and he's not sure if it's love -- or if she's a ruthless con artist who's using him to find the fabled Fountain of Youth. When she forces him aboard the Queen Anne's Revenge, the ship of the formidable pirate Blackbeard, Jack finds himself on an unexpected adventure in which he doesn't know who to fear more: Blackbeard or the woman from his past. | M19: 135413856 | N19: [{"name": "Walt Disney Pictures", "id": 2}, {"name": "Jerry Bruckheimer Films", "id": 130}, {"name": "Moving Picture Company (MPC)", "id": 20478}] | O19: Walt Disney Pictures | P19: [{"iso_3166_1": "US", "name": "United States of America"}] | Q19: 40677 | R19: 2011 | S19: 1045713802 | T19: 136 | U19: [{"iso_639_1": "en", "name": "English"}, {"iso_639_1": "es", "name": "Espa\u00f1ol"}] | V19: Released | W19: Live Forever Or Die Trying. | X19: 6.4 | Y19: 4948 | Z19: 665713802
A20: 225000000 | B20: [{ 28, name: Action}, { 35, name: Comedy}, { 878, name: Science Fiction}] | C20: Action | D20: Comedy | E20: Science Fiction | F20: - | G20: http://www.sonypictures.com/movies/meninblack3/ | H20: 41154 | I20: Men in Black 3 | J20: [{"id": 4379, "name": "time travel"}, {"id": 5455, "name": "time machine"}, {"id": 9951, "name": "alien"}, {"id": 174915, "name": "fictional government agency"}, {"id": 185668, "name": "seeing the future"}, {"id": 208756, "name": "changing history"}] | K20: en | L20: Agents J (Will Smith) and K (Tommy Lee Jones) are back...in time. J has seen some inexplicable things in his 15 years with the Men in Black, but nothing, not even aliens, perplexes him as much as his wry, reticent partner. But when K's life and the fate of the planet are put at stake, Agent J will have to travel back in time to put things right. J discovers that there are secrets to the universe that K never told him - secrets that will reveal themselves as he teams up with the young Agent K (Josh Brolin) to save his partner, the agency, and the future of humankind. | M20: 52035179 | N20: [{"name": "Amblin Entertainment", "id": 56}, {"name": "Media Magik Entertainment", "id": 5627}, {"name": "Imagenation Abu Dhabi FZ", "id": 6736}, {"name": "Hemisphere Media Capital", "id": 9169}, {"name": "Parkes/MacDonald Productions", "id": 11084}] | O20: Amblin Entertainment | P20: [{"iso_3166_1": "US", "name": "United States of America"}] | Q20: 41052 | R20: 2012 | S20: 624026776 | T20: 106 | U20: [{"iso_639_1": "en", "name": "English"}] | V20: Released | W20: They are back... in time. | X20: 6.2 | Y20: 4160 | Z20: 399026776
A21: 250000000 | B21: [{ 28, name: Action}, { 12, name: Adventure}, { 14, name: Fantasy}] | C21: Action | D21: Adventure | E21: Fantasy | F21: - | G21: http://www.thehobbit.com/ | H21: 122917 | I21: The Hobbit: The Battle of the Five Armies | J21: [{"id": 417, "name": "corruption"}, {"id": 603, "name": "elves"}, {"id": 604, "name": "dwarves"}, {"id": 606, "name": "orcs"}, {"id": 609, "name": "middle-earth (tolkien)"}, {"id": 611, "name": "hobbit"}, {"id": 12554, "name": "dragon"}, {"id": 14643, "name": "battle"}, {"id": 167982, "name": "unlikely friendship"}, {"id": 188270, "name": "epic battle"}, {"id": 234213, "name": "sword and sorcery"}] | K21: en | L21: Immediately after the events of The Desolation of Smaug, Bilbo and the dwarves try to defend Erebor's mountain of treasure from others who claim it: the men of the ruined Laketown and the elves of Mirkwood. Meanwhile an army of Orcs led by Azog the Defiler is marching on Erebor, fueled by the rise of the dark lord Sauron. Dwarves, elves and men must unite, and the hope for Middle-Earth falls into Bilbo's hands. | M21: 120965743 | N21: [{"name": "WingNut Films", "id": 11}, {"name": "New Line Cinema", "id": 12}, {"name": "Warner Bros. Pictures", "id": 174}, {"name": "3Foot7", "id": 7413}, {"name": "Metro-Goldwyn-Mayer (MGM)", "id": 8411}] | O21: WingNut Films | P21: [{"iso_3166_1": "NZ", "name": "New Zealand"}, {"iso_3166_1": "US", "name": "United States of America"}] | Q21: 41983 | R21: 2014 | S21: 956019788 | T21: 144 | U21: [{"iso_639_1": "en", "name": "English"}] | V21: Released | W21: Witness the defining chapter of the Middle-Earth saga | X21: 7.1 | Y21: 4760 | Z21: 706019788
A22: 215000000 | B22: [{ 28, name: Action}, { 12, name: Adventure}, { 14, name: Fantasy}] | C22: Action | D22: Adventure | E22: Fantasy | F22: - | G22: http://www.theamazingspiderman.com | H22: 1930 | I22: The Amazing Spider-Man | J22: [{"id": 1872, "name": "loss of father"}, {"id": 7002, "name": "vigilante"}, {"id": 8803, "name": "serum"}, {"id": 8828, "name": "marvel comic"}, {"id": 156855, "name": "scientific experiment"}, {"id": 158124, "name": "spider bite"}, {"id": 158456, "name": "masked vigilante"}, {"id": 161184, "name": "reboot"}, {"id": 163455, "name": "super powers"}, {"id": 163561, "name": "genetic engineering"}, {"id": 171556, "name": "social outcast"}, {"id": 179431, "name": "duringcreditsstinger"}] | K22: en | L22: Peter Parker is an outcast high schooler abandoned by his parents as a boy, leaving him to be raised by his Uncle Ben and Aunt May. Like most teenagers, Peter is trying to figure out who he is and how he got to be the person he is today. As Peter discovers a mysterious briefcase that belonged to his father, he begins a quest to understand his parents' disappearance â€“ leading him directly to Oscorp and the lab of Dr. Curt Connors, his father's former partner. As Spider-Man is set on a collision course with Connors' alter ego, The Lizard, Peter will make life-altering choices to use his powers and shape his destiny to become a hero. | M22: 89866276 | N22: [{"name": "Columbia Pictures", "id": 5}, {"name": "Laura Ziskin Productions", "id": 326}, {"name": "Marvel Entertainment", "id": 7505}] | O22: Columbia Pictures | P22: [{"iso_3166_1": "US", "name": "United States of America"}] | Q22: 41087 | R22: 2012 | S22: 752215857 | T22: 136 | U22: [{"iso_639_1": "en", "name": "English"}] | V22: Released | W22: The untold story begins. | X22: 6.5 | Y22: 6586 | Z22: 537215857
A23: 250000000 | B23: [{ 12, name: Adventure}, { 14, name: Fantasy}] | C23: Adventure | D23: Fantasy | E23: - | F23: - | G23: http://www.thehobbit.com/ | H23: 57158 | I23: The Hobbit: The Desolation of Smaug | J23: [{"id": 603, "name": "elves"}, {"id": 604, "name": "dwarves"}, {"id": 606, "name": "orcs"}, {"id": 611, "name": "hobbit"}, {"id": 12554, "name": "dragon"}, {"id": 177912, "name": "wizard"}, {"id": 234213, "name": "sword and sorcery"}] | K23: en | L23: The Dwarves, Bilbo and Gandalf have successfully escaped the Misty Mountains, and Bilbo has gained the One Ring. They all continue their journey to get their gold back from the Dragon, Smaug. | M23: 94370564 | N23: [{"name": "WingNut Films", "id": 11}, {"name": "New Line Cinema", "id": 12}, {"name": "Warner Bros. Pictures", "id": 174}, {"name": "Metro-Goldwyn-Mayer (MGM)", "id": 8411}] | O23: WingNut Films | P23: [{"iso_3166_1": "NZ", "name": "New Zealand"}, {"iso_3166_1": "US", "name": "United States of America"}] | Q23: 41619 | R23: 2013 | S23: 958400000 | T23: 161 | U23: [{"iso_639_1": "en", "name": "English"}] | V23: Released | W23: Beyond darkness... beyond desolation... lies the greatest danger of all. | X23: 7.6 | Y23: 4524 | Z23: 708400000
A24: 180000000 | B24: [{ 12, name: Adventure}, { 14, name: Fantasy}] | C24: Adventure | D24: Fantasy | E24: - | F24: - | G24: http://www.goldencompassmovie.com/index_german.html | H24: 2268 | I24: The Golden Compass | J24: [{"id": 392, "name": "england"}, {"id": 1461, "name": "compass"}, {"id": 1706, "name": "experiment"}, {"id": 2596, "name": "lordship"}, {"id": 6464, "name": "uncle"}, {"id": 6678, "name": "polar bear"}, {"id": 13014, "name": "orphan"}, {"id": 18165, "name": "animal"}, {"id": 223438, "name": "based on young adult novel"}] | K24: en | L24: After overhearing a shocking secret, precocious orphan Lyra Belacqua trades her carefree existence roaming the halls of Jordan College for an otherworldly adventure in the far North, unaware that it's part of her destiny. | M24: 42990906 | N24: [{"name": "New Line Cinema", "id": 12}, {"name": "Ingenious Film Partners", "id": 289}, {"name": "Depth of Field", "id": 1473}, {"name": "Scholastic Productions", "id": 1938}] | O24: New Line Cinema | P24: [{"iso_3166_1": "GB", "name": "United Kingdom"}, {"iso_3166_1": "US", "name": "United States of America"}] | Q24: 39420 | R24: 2007 | S24: 372234864 | T24: 113 | U24: [{"iso_639_1": "is", "name": "\u00cdslenska"}, {"iso_639_1": "en", "name": "English"}, {"iso_639_1": "ru", "name": "P\u0443\u0441\u0441\u043a\u0438\u0439"}, {"iso_639_1": "fr", "name": "Fran\u00e7ais"}] | V24: Released | W24: There are worlds beyond our own - the compass will show the way. | X24: 5.8 | Y24: 1303 | Z24: 192234864
A25: 207000000 | B25: [{ 12, name: Adventure}, { 18, name: Drama}, { 28, name: Action}] | C25: Adventure | D25: Drama | E25: Action | F25: - | H25: 254 | I25: King Kong | J25: [{"id": 774, "name": "film business"}, {"id": 776, "name": "screenplay"}, {"id": 837, "name": "show business"}, {"id": 886, "name": "film making"}, {"id": 887, "name": "film producer"}, {"id": 911, "name": "exotic island"}, {"id": 1299, "name": "monster"}, {"id": 1551, "name": "indigenous"}, {"id": 3799, "name": "ship"}, {"id": 12616, "name": "dinosaur"}] | K25: en | L25: In 1933 New York, an overly ambitious movie producer coerces his cast and hired ship crew to travel to mysterious Skull Island, where they encounter Kong, a giant ape who is immediately smitten with the leading lady. | M25: 6122601 | N25: [{"name": "WingNut Films", "id": 11}, {"name": "Universal Pictures", "id": 33}, {"name": "Big Primate Pictures", "id": 68}, {"name": "MFPV Film", "id": 69}] | O25: WingNut Films | P25: [{"iso_3166_1": "NZ", "name": "New Zealand"}, {"iso_3166_1": "US", "name": "United States of America"}, {"iso_3166_1": "DE", "name": "Germany"}] | Q25: 38700 | R25: 2005 | S25: 550000000 | T25: 187 | U25: [{"iso_639_1": "en", "name": "English"}] | V25: Released | W25: The eighth wonder of the world. | X25: 6.6 | Y25: 2337 | Z25: 343000000
A26: 200000000 | B26: [{ 18, name: Drama}, { 10749, name: Romance}, { 53, name: Thriller}] | C26: Drama | D26: Romance | E26: Thriller | F26: - | G26: http://www.titanicmovie.com | H26: 597 | I26: Titanic | J26: [{"id": 2580, "name": "shipwreck"}, {"id": 2984, "name": "iceberg"}, {"id": 3799, "name": "ship"}, {"id": 4210, "name": "panic"}, {"id": 4388, "name": "titanic"}, {"id": 4953, "name": "ocean liner"}, {"id": 6917, "name": "epic"}, {"id": 7579, "name": "rich woman - poor man"}, {"id": 9673, "name": "love"}, {"id": 10617, "name": "disaster"}, {"id": 10703, "name": "tragic love"}, {"id": 14514, "name": "class differences"}, {"id": 156395, "name": "imax"}, {"id": 165086, "name": "star crossed lovers"}, {"id": 182615, "name": "steerage"}, {"id": 182621, "name": "salvage"}, {"id": 182625, "name": "rich snob"}, {"id": 209714, "name": "3d"}, {"id": 210184, "name": "1910s"}] | K26: en | L26: 84 years later, a 101-year-old woman named Rose DeWitt Bukater tells the story to her granddaughter Lizzy Calvert, Brock Lovett, Lewis Bodine, Bobby Buell and Anatoly Mikailavich on the Keldysh about her life set in April 10th 1912, on a ship called Titanic when young Rose boards the departing ship with the upper-class passengers and her mother, Ruth DeWitt Bukater, and her fiancÃ©, Caledon Hockley. Meanwhile, a drifter and artist named Jack Dawson and his best friend Fabrizio De Rossi win third-class tickets to the ship in a game. And she explains the whole story from departure until the death of Titanic on its first and last voyage April 15th, 1912 at 2:20 in the morning. | M26: 100025899 | N26: [{"name": "Paramount Pictures", "id": 4}, {"name": "Twentieth Century Fox Film Corporation", "id": 306}, {"name": "Lightstorm Entertainment", "id": 574}] | O26: Paramount Pictures | P26: [{"iso_3166_1": "US", "name": "United States of America"}] | Q26: 35752 | R26: 1997 | S26: 1845034188 | T26: 194 | U26: [{"iso_639_1": "en", "name": "English"}, {"iso_639_1": "fr", "name": "Fran\u00e7ais"}, {"iso_639_1": "de", "name": "Deutsch"}, {"iso_639_1": "sv", "name": "svenska"}, {"iso_639_1": "it", "name": "Italiano"}, {"iso_639_1": "ru", "name": "P\u0443\u0441\u0441\u043a\u0438\u0439"}] | V26: Released | W26: Nothing on Earth could come between them. | X26: 7.5 | Y26: 7562 | Z26: 1645034188
A27: 250000000 | B27: [{ 12, name: Adventure}, { 28, name: Action}, { 878, name: Science Fiction}] | C27: Adventure | D27: Action | E27: Science Fiction | F27: - | G27: http://marvel.com/captainamericapremiere | H27: 271110 | I27: Captain America: Civil War | J27: [{"id": 393, "name": "civil war"}, {"id": 6091, "name": "war"}, {"id": 8828, "name": "marvel comic"}, {"id": 9663, "name": "sequel"}, {"id": 9715, "name": "superhero"}, {"id": 9717, "name": "based on comic book"}, {"id": 156395, "name": "imax"}, {"id": 179430, "name": "aftercreditsstinger"}, {"id": 179431, "name": "duringcreditsstinger"}, {"id": 180547, "name": "marvel cinematic universe"}, {"id": 209714, "name": "3d"}] | K27: en | L27: Following the events of Age of Ultron, the collective governments of the world pass an act designed to regulate all superhuman activity. This polarizes opinion amongst the Avengers, causing two factions to side with Iron Man or Captain America, which causes an epic battle between former allies. | M27: 198372395 | N27: [{"name": "Studio Babelsberg", "id": 264}, {"name": "Marvel Studios", "id": 420}, {"name": "Walt Disney Studios Motion Pictures", "id": 3036}, {"name": "Vita-Ray Dutch Productions (III)", "id": 84424}, {"name": "Deluxe Digital Studios", "id": 84425}] | O27: Studio Babelsberg | P27: [{"iso_3166_1": "US", "name": "United States of America"}] | Q27: 42487 | R27: 2016 | S27: 1153304495 | T27: 147 | U27: [{"iso_639_1": "ro", "name": "Rom\u00e2n\u0103"}, {"iso_639_1": "en", "name": "English"}, {"iso_639_1": "de", "name": "Deutsch"}, {"iso_639_1": "ru", "name": "P\u0443\u0441\u0441\u043a\u0438\u0439"}] | V27: Released | W27: Divided We Fall | X27: 7.1 | Y27: 7241 | Z27: 903304495
A28: 74000000 | B28: [{ 10751, name: Family}, { 16, name: Animation}, { 12, name: Adventure}, { 35, name: Comedy}] | C28: Family | D28: Animation | E28: Adventure | F28: Comedy | G28: http://www.minionsmovie.com/ | H28: 211672 | I28: Minions | J28: [{"id": 3487, "name": "assistant"}, {"id": 179430, "name": "aftercreditsstinger"}, {"id": 179431, "name": "duringcreditsstinger"}, {"id": 189481, "name": "evil mastermind"}, {"id": 190999, "name": "minions"}, {"id": 209714, "name": "3d"}] | K28: en | L28: Minions Stuart, Kevin and Bob are recruited by Scarlet Overkill, a super-villain who, alongside her inventor husband Herb, hatches a plot to take over the world. | M28: 875581305 | N28: [{"name": "Universal Pictures", "id": 33}, {"name": "Illumination Entertainment", "id": 6704}] | O28: Universal Pictures | P28: [{"iso_3166_1": "US", "name": "United States of America"}] | Q28: 42172 | R28: 2015 | S28: 1156730962 | T28: 91 | U28: [{"iso_639_1": "en", "name": "English"}] | V28: Released | W28: Before Gru, they had a history of bad bosses | X28: 6.4 | Y28: 4571 | Z28: 1082730962
A29: 150000000 | B29: [{ 28, name: Action}, { 12, name: Adventure}, { 878, name: Science Fiction}, { 53, name: Thriller}] | C29: Action | D29: Adventure | E29: Science Fiction | F29: Thriller | G29: http://www.jurassicworld.com/ | H29: 135397 | I29: Jurassic World | J29: [{"id": 1299, "name": "monster"}, {"id": 1718, "name": "dna"}, {"id": 1720, "name": "tyrannosaurus rex"}, {"id": 1766, "name": "velociraptor"}, {"id": 2041, "name": "island"}, {"id": 9663, "name": "sequel"}, {"id": 9937, "name": "suspense"}, {"id": 10617, "name": "disaster"}, {"id": 10685, "name": "escape"}, {"id": 12616, "name": "dinosaur"}, {"id": 155582, "name": "amusement park"}, {"id": 158130, "name": "animal attack"}, {"id": 158340, "name": "theme park"}, {"id": 178010, "name": "jurassic park"}, {"id": 209714, "name": "3d"}, {"id": 223059, "name": "animal horror"}] | K29: en | L29: Twenty-two years after the events of Jurassic Park, Isla Nublar now features a fully functioning dinosaur theme park, Jurassic World, as originally envisioned by John Hammond. | M29: 418708552 | N29: [{"name": "Universal Studios", "id": 13}, {"name": "Amblin Entertainment", "id": 56}, {"name": "Legendary Pictures", "id": 923}, {"name": "Fuji Television Network", "id": 3341}, {"name": "Dentsu", "id": 6452}] | O29: Universal Studios | P29: [{"iso_3166_1": "US", "name": "United States of America"}] | Q29: 42164 | R29: 2015 | S29: 1513528810 | T29: 124 | U29: [{"iso_639_1": "en", "name": "English"}] | V29: Released | W29: The park is open. | X29: 6.5 | Y29: 8662 | Z29: 1363528810
A30: 200000000 | B30: [{ 28, name: Action}, { 12, name: Adventure}, { 53, name: Thriller}] | C30: Action | D30: Adventure | E30: Thriller | F30: - | G30: http://www.skyfall-movie.com | H30: 37724 | I30: Skyfall | J30: [{"id": 470, "name": "spy"}, {"id": 4289, "name": "secret agent"}, {"id": 9740, "name": "sociopath"}, {"id": 15127, "name": "killer"}, {"id": 15478, "name": "art gallery"}, {"id": 156095, "name": "british secret service"}, {"id": 156345, "name": "istanbul turkey"}, {"id": 156395, "name": "imax"}, {"id": 159932, "name": "uzi"}, {"id": 163841, "name": "booby trap"}, {"id": 185071, "name": "impersonating a police officer"}, {"id": 185077, "name": "macao"}] | K30: en | L30: When Bond's latest assignment goes gravely wrong and agents around the world are exposed, MI6 is attacked forcing M to relocate the agency. These events cause her authority and position to be challenged by Gareth Mallory, the new Chairman of the Intelligence and Security Committee. With MI6 now compromised from both inside and out, M is left with one ally she can trust: Bond. 007 takes to the shadows - aided only by field agent, Eve - following a trail to the mysterious Silva, whose lethal and hidden motives have yet to reveal themselves. | M30: 93004993 | N30: [{"name": "Columbia Pictures", "id": 5}] | O30: Columbia Pictures | P30: [{"iso_3166_1": "GB", "name": "United Kingdom"}, {"iso_3166_1": "US", "name": "United States of America"}] | Q30: 41207 | R30: 2012 | S30: 1108561013 | T30: 143 | U30: [{"iso_639_1": "en", "name": "English"}] | V30: Released | W30: Think on your sins. | X30: 6.9 | Y30: 7604 | Z30: 908561013
A31: 200000000 | B31: [{ 28, name: Action}, { 12, name: Adventure}, { 14, name: Fantasy}] | C31: Action | D31: Adventure | E31: Fantasy | F31: - | G31: http://www.sonypictures.com/movies/spider-man2/ | H31: 558 | I31: Spider-Man 2 | J31: [{"id": 851, "name": "dual identity"}, {"id": 2038, "name": "love of one's life"}, {"id": 5983, "name": "pizza boy"}, {"id": 8828, "name": "marvel comic"}, {"id": 9663, "name": "sequel"}, {"id": 9715, "name": "superhero"}, {"id": 13005, "name": "doctor"}, {"id": 14760, "name": "scientist"}, {"id": 14991, "name": "tentacle"}, {"id": 34079, "name": "death"}, {"id": 163074, "name": "super villain"}] | K31: en | L31: Peter Parker is going through a major identity crisis. Burned out from being Spider-Man, he decides to shelve his superhero alter ego, which leaves the city suffering in the wake of carnage left by the evil Doc Ock. In the meantime, Parker still can't act on his feelings for Mary Jane Watson, a girl he's loved since childhood. | M31: 35149586 | N31: [{"name": "Columbia Pictures", "id": 5}, {"name": "Laura Ziskin Productions", "id": 326}, {"name": "Marvel Enterprises", "id": 19551}] | O31: Columbia Pictures | P31: [{"iso_3166_1": "US", "name": "United States of America"}] | Q31: 38163 | R31: 2004 | S31: 783766341 | T31: 127 | U31: [{"iso_639_1": "en", "name": "English"}, {"iso_639_1": "ru", "name": "P\u0443\u0441\u0441\u043a\u0438\u0439"}, {"iso_639_1": "zh", "name": "\u666e\u901a\u8bdd"}] | V31: Released | W31: There's a hero in all of us. | X31: 6.7 | Y31: 4321 | Z31: 583766341
A32: 200000000 | B32: [{ 28, name: Action}, { 12, name: Adventure}, { 878, name: Science Fiction}] | C32: Action | D32: Adventure | E32: Science Fiction | F32: - | G32: http://marvel.com/ironman3 | H32: 68721 | I32: Iron Man 3 | J32: [{"id": 949, "name": "terrorist"}, {"id": 5597, "name": "war on terror"}, {"id": 6335, "name": "tennessee"}, {"id": 8613, "name": "malibu"}, {"id": 8828, "name": "marvel comic"}, {"id": 9715, "name": "superhero"}, {"id": 9717, "name": "based on comic book"}, {"id": 12555, "name": "tony stark"}, {"id": 173776, "name": "iron man"}, {"id": 179430, "name": "aftercreditsstinger"}, {"id": 180547, "name": "marvel cinematic universe"}, {"id": 188721, "name": "mandarin"}, {"id": 209714, "name": "3d"}, {"id": 209748, "name": "war machine"}, {"id": 209822, "name": "iron patriot"}, {"id": 209823, "name": "extremis"}] | K32: en | L32: When Tony Stark's world is torn apart by a formidable terrorist called the Mandarin, he starts an odyssey of rebuilding and retribution. | M32: 7768208 | N32: [{"name": "Marvel Studios", "id": 420}] | O32: Marvel Studios | P32: [{"iso_3166_1": "CN", "name": "China"}, {"iso_3166_1": "US", "name": "United States of America"}] | Q32: 41382 | R32: 2013 | S32: 1215439994 | T32: 130 | U32: [{"iso_639_1": "en", "name": "English"}] | V32: Released | W32: Unleash the power behind the armor. | X32: 6.8 | Y32: 8806 | Z32: 1015439994
A33: 200000000 | B33: [{ 10751, name: Family}, { 14, name: Fantasy}, { 12, name: Adventure}] | C33: Family | D33: Fantasy | E33: Adventure | F33: - | G33: http://disney.go.com/wonderland/ | H33: 12155 | I33: Alice in Wonderland | J33: [{"id": 818, "name": "based on novel"}, {"id": 855, "name": "fictional place"}, {"id": 2011, "name": "queen"}, {"id": 2486, "name": "fantasy"}, {"id": 12552, "name": "alice in wonderland"}, {"id": 170362, "name": "fantasy world"}, {"id": 209714, "name": "3d"}] | K33: en | L33: Alice, an unpretentious and individual 19-year-old, is betrothed to a dunce of an English nobleman. At her engagement party, she escapes the crowd to consider whether to go through with the marriage and falls down a hole in the garden after spotting an unusual rabbit. Arriving in a strange and surreal place called 'Underland,' she finds herself in a world that resembles the nightmares she had as a child, filled with talking animals, villainous queens and knights, and frumious bandersnatches. Alice realizes that she is there for a reason â€“ to conquer the horrific Jabberwocky and restore the rightful queen to her throne. | M33: 78530105 | N33: [{"name": "Walt Disney Pictures", "id": 2}, {"name": "Team Todd", "id": 598}, {"name": "Tim Burton Productions", "id": 8601}, {"name": "Roth Films", "id": 16314}, {"name": "Zanuck Company, The", "id": 20004}] | O33: Walt Disney Pictures | P33: [{"iso_3166_1": "US", "name": "United States of America"}] | Q33: 40240 | R33: 2010 | S33: 1025491110 | T33: 108 | U33: [{"iso_639_1": "en", "name": "English"}] | V33: Released | W33: You're invited to a very important date. | X33: 6.4 | Y33: 4645 | Z33: 825491110
A34: 210000000 | B34: [{ 12, name: Adventure}, { 28, name: Action}, { 878, name: Science Fiction}, { 53, name: Thriller}] | C34: Adventure | D34: Action | E34: Science Fiction | F34: Thriller | H34: 36668 | I34: X-Men: The Last Stand | J34: [{"id": 1852, "name": "mutant"}, {"id": 8828, "name": "marvel comic"}, {"id": 9717, "name": "based on comic book"}, {"id": 10761, "name": "superhuman"}, {"id": 161271, "name": "beast"}, {"id": 161893, "name": "cyclops"}, {"id": 179430, "name": "aftercreditsstinger"}] | K34: en | L34: When a cure is found to treat mutations, lines are drawn amongst the X-Men and The Brotherhood, a band of powerful mutants organized under Xavier's former ally, Magneto. | M34: 3857526 | N34: [{"name": "Ingenious Film Partners", "id": 289}, {"name": "Twentieth Century Fox Film Corporation", "id": 306}, {"name": "Donners' Company", "id": 431}, {"name": "Dune Entertainment", "id": 444}, {"name": "Major Studio Partners", "id": 445}, {"name": "Bad Hat Harry Productions", "id": 9168}, {"name": "thinkfilm", "id": 12247}, {"name": "Marvel Enterprises", "id": 19551}, {"name": "X3 Canada Productions", "id": 79028}, {"name": "X3US Productions", "id": 79029}, {"name": "XM3 Service", "id": 79030}] | O34: Ingenious Film Partners | P34: [{"iso_3166_1": "CA", "name": "Canada"}, {"iso_3166_1": "GB", "name": "United Kingdom"}, {"iso_3166_1": "US", "name": "United States of America"}] | Q34: 38861 | R34: 2006 | S34: 459359555 | T34: 104 | U34: [{"iso_639_1": "en", "name": "English"}] | V34: Released | W34: Take a Stand | X34: 6.3 | Y34: 3525 | Z34: 249359555
